Workbook

Sheet Hot Hand Rankings
B1: Andre | C1: Coach | D1: Junior | E1: Masta Pu$$y | F1: Moe | G1: Mrs. Clay Matthews | H1: Princess Peach | I1: Screech | J1: Siri | K1: The Bieb | L1: Waxcuses
A2: Attendance | B2: =COUNTIF('Raw Data'!H142:H153,"Yes") -> 6 | C2: =COUNTIF('Raw Data'!I142:I153,"Yes") -> 10 | D2: =COUNTIF('Raw Data'!J142:J153,"Yes") -> 11 | E2: =COUNTIF('Raw Data'!K142:K153,"Yes") -> 6 | F2: =COUNTIF('Raw Data'!L142:L153,"Yes") -> 12 | G2: =COUNTIF('Raw Data'!M142:M153,"Yes") -> 11 | H2: =COUNTIF('Raw Data'!N142:N153,"Yes") -> 0 | I2: =COUNTIF('Raw Data'!O142:O153,"Yes") -> 12 | ... L2: =COUNTIF('Raw Data'!R142:R153,"Yes") -> 7
A3: Bracelets | B3: =(COUNTIF('Raw Data'!$F142:$F153,B1))*2 -> 0 | C3: =(COUNTIF('Raw Data'!$F142:$F153,C1))*2 -> 4 | D3: =(COUNTIF('Raw Data'!$F142:$F153,D1))*2 -> 4 | E3: =(COUNTIF('Raw Data'!$F142:$F153,E1))*2 -> 2 | F3: =(COUNTIF('Raw Data'!$F142:$F153,F1))*2 -> 2 | G3: =(COUNTIF('Raw Data'!$F142:$F153,G1))*2 -> 0 | H3: =(COUNTIF('Raw Data'!$F142:$F153,H1))*2 -> 0 | I3: =(COUNTIF('Raw Data'!$F142:$F153,I1))*2 -> 10 | ... L3: =(COUNTIF('Raw Data'!$F142:$F153,L1))*2 -> 0
A4: Majors | B4: =(COUNTIFS('Raw Data'!$D142:$D153,"Yes",'Raw Data'!$F142:$F153,B1))*4 -> 0 | C4: =COUNTIFS('Raw Data'!$D142:$D153,"Yes",'Raw Data'!$F142:$F153,C1) -> 0 | D4: =COUNTIFS('Raw Data'!$D142:$D153,"Yes",'Raw Data'!$F142:$F153,D1) -> 0 | E4: =COUNTIFS('Raw Data'!$D142:$D153,"Yes",'Raw Data'!$F142:$F153,E1) -> 0 | F4: =COUNTIFS('Raw Data'!$D142:$D153,"Yes",'Raw Data'!$F142:$F153,F1) -> 0 | G4: =COUNTIFS('Raw Data'!$D142:$D153,"Yes",'Raw Data'!$F142:$F153,G1) -> 0 | H4: =COUNTIFS('Raw Data'!$D142:$D153,"Yes",'Raw Data'!$F142:$F153,H1) -> 0 | I4: =COUNTIFS('Raw Data'!$D142:$D153,"Yes",'Raw Data'!$F142:$F153,I1) -> 0 | J4: =COUNTIFS('Raw Data'!$D142:$D153,"Yes",'Raw Data'!$F142:$F153,J1) -> 0 | ... L4: =COUNTIFS('Raw Data'!$D142:$D153,"Yes",'Raw Data'!$F142:$F153,L1) -> 0
A5: Exceeds Exp. | B5: 0 | C5: 0 | D5: 0 | E5: 0 | F5: 0 | G5: 0 | H5: 0 | I5: 0 | J5: 0 | K5: 0 | L5: 0
A6: Total | B6: =sum(B2:B5) -> 6 | C6: =sum(C2:C5) -> 14 | D6: =sum(D2:D5) -> 15 | E6: =sum(E2:E5) -> 8 | F6: =sum(F2:F5) -> 14 | G6: =sum(G2:G5) -> 11 | H6: =sum(H2:H5) -> 0 | I6: =sum(I2:I5) -> 22 | ... L6: =sum(L2:L5) -> 7
A8: Ranking | B8: Player | C8: HH Points
A9: 1 | B9: Screech | C9: =$I$6 -> 22
A10: 2 | B10: Junior | C10: =$D$6 -> 15
A11: 3 | B11: Coach | C11: =$C$6 -> 14
A12: 4 | B12: Moe | C12: =$F$6 -> 14
A13: 5 | B13: Siri | C13: =$J$6 -> 12
A14: 6 | B14: Mrs. Clay Matthews | C14: =$G$6 -> 11
A15: 7 | B15: Masta Pu$$y | C15: =$E$6 -> 8
A16: 8 | B16: The Bieb | C16: =$K$6 -> 7
A17: 9 | B17: Waxcuses | C17: =$L$6 -> 7
A18: 10 | B18: Andre | C18: =$B$6 -> 6
A19: Princess Peach | B19: =$H$6 -> 0

Sheet Raw Data
A1: Event # | B1: Date | C1: Season | E1: Host | F1: Winner | G1: Attendance | H1: Andre | I1: Coach | J1: Junior | K1: Masta Pu$$y | L1: Moe | M1: Mrs. Clay Matthews | N1: Princess Peach | O1: Screech | P1: Siri | Q1: The Bieb | R1: Waxcuses | S1: Flo Rida | T1: No Limit | V1: Andre | W1: Coach | X1: Junior | Y1: Masta Pu$$y | Z1: Moe | AA1: Mrs. Clay Matthews | AB1: Princess Peach | AC1: Screech | AD1: Siri | AE1: The Bieb | AF1: Waxcuses | AG1: Flo Rida | AH1: No Limit
A2: 1 | B2: 39394 | C2: 2007-2009 | D2: No | E2: Coach | F2: Coach | G2: =countif(H2:R2,"Yes") -> 6 | H2: Yes | I2: Yes | K2: Yes | L2: Yes | N2: No | P2: Yes | R2: Yes | V2: =COUNTIF($F$2:$F2,V$1) -> 0 | W2: =COUNTIF($F$2:$F2,W$1) -> 1 | X2: =COUNTIF($F$2:$F2,X$1) -> 0 | Y2: =COUNTIF($F$2:$F2,Y$1) -> 0 | Z2: =COUNTIF($F$2:$F2,Z$1) -> 0 | AA2: =COUNTIF($F$2:$F2,AA$1) -> 0 | AB2: =COUNTIF($F$2:$F2,AB$1) -> 0 | AC2: =COUNTIF($F$2:$F2,AC$1) -> 0 | ... AH2: =COUNTIF($F$2:$F2,AH$1) -> 0
A3: 2 | B3: 39626 | C3: 2007-2009 | D3: No | E3: Coach | F3: Waxcuses | G3: =countif(H3:R3,"Yes") -> 7 | H3: Yes | I3: Yes | K3: Yes | L3: Yes | N3: Yes | P3: Yes | R3: Yes | V3: =COUNTIF($F$2:$F3,V$1) -> 0 | W3: =COUNTIF($F$2:$F3,W$1) -> 1 | X3: =COUNTIF($F$2:$F3,X$1) -> 0 | Y3: =COUNTIF($F$2:$F3,Y$1) -> 0 | Z3: =COUNTIF($F$2:$F3,Z$1) -> 0 | AA3: =COUNTIF($F$2:$F3,AA$1) -> 0 | AB3: =COUNTIF($F$2:$F3,AB$1) -> 0 | AC3: =COUNTIF($F$2:$F3,AC$1) -> 0 | ... AH3: =COUNTIF($F$2:$F3,AH$1) -> 0
A4: 3 | B4: 39786 | C4: 2007-2009 | D4: No | E4: Siri | F4: Moe | G4: =countif(H4:R4,"Yes") -> 7 | H4: Yes | I4: Yes | K4: Yes | L4: Yes | N4: Yes | P4: Yes | R4: Yes | V4: =COUNTIF($F$2:$F4,V$1) -> 0 | W4: =COUNTIF($F$2:$F4,W$1) -> 1 | X4: =COUNTIF($F$2:$F4,X$1) -> 0 | Y4: =COUNTIF($F$2:$F4,Y$1) -> 0 | Z4: =COUNTIF($F$2:$F4,Z$1) -> 1 | AA4: =COUNTIF($F$2:$F4,AA$1) -> 0 | AB4: =COUNTIF($F$2:$F4,AB$1) -> 0 | AC4: =COUNTIF($F$2:$F4,AC$1) -> 0 | ... AH4: =COUNTIF($F$2:$F4,AH$1) -> 0
A5: 4 | B5: 39815 | C5: 2007-2009 | D5: No | E5: Moe | F5: Coach | G5: =countif(H5:R5,"Yes") -> 7 | H5: Yes | I5: Yes | K5: Yes | L5: Yes | N5: Yes | P5: Yes | R5: Yes | V5: =COUNTIF($F$2:$F5,V$1) -> 0 | W5: =COUNTIF($F$2:$F5,W$1) -> 2 | X5: =COUNTIF($F$2:$F5,X$1) -> 0 | Y5: =COUNTIF($F$2:$F5,Y$1) -> 0 | Z5: =COUNTIF($F$2:$F5,Z$1) -> 1 | AA5: =COUNTIF($F$2:$F5,AA$1) -> 0 | AB5: =COUNTIF($F$2:$F5,AB$1) -> 0 | AC5: =COUNTIF($F$2:$F5,AC$1) -> 0 | ... AH5: =COUNTIF($F$2:$F5,AH$1) -> 0
A6: 5 | B6: 39856 | C6: 2007-2009 | D6: No | E6: Andre | F6: Siri | G6: =countif(H6:R6,"Yes") -> 7 | H6: Yes | I6: Yes | K6: Yes | L6: Yes | N6: Yes | P6: Yes | R6: Yes | V6: =COUNTIF($F$2:$F6,V$1) -> 0 | W6: =COUNTIF($F$2:$F6,W$1) -> 2 | X6: =COUNTIF($F$2:$F6,X$1) -> 0 | Y6: =COUNTIF($F$2:$F6,Y$1) -> 0 | Z6: =COUNTIF($F$2:$F6,Z$1) -> 1 | AA6: =COUNTIF($F$2:$F6,AA$1) -> 0 | AB6: =COUNTIF($F$2:$F6,AB$1) -> 0 | AC6: =COUNTIF($F$2:$F6,AC$1) -> 0 | ... AH6: =COUNTIF($F$2:$F6,AH$1) -> 0
A7: 6 | B7: 39884 | C7: 2007-2009 | D7: No | E7: Princess Peach | F7: Siri | G7: =countif(H7:R7,"Yes") -> 7 | H7: Yes | I7: Yes | K7: Yes | L7: Yes | N7: Yes | P7: Yes | R7: Yes | V7: =COUNTIF($F$2:$F7,V$1) -> 0 | W7: =COUNTIF($F$2:$F7,W$1) -> 2 | X7: =COUNTIF($F$2:$F7,X$1) -> 0 | Y7: =COUNTIF($F$2:$F7,Y$1) -> 0 | Z7: =COUNTIF($F$2:$F7,Z$1) -> 1 | AA7: =COUNTIF($F$2:$F7,AA$1) -> 0 | AB7: =COUNTIF($F$2:$F7,AB$1) -> 0 | AC7: =COUNTIF($F$2:$F7,AC$1) -> 0 | ... AH7: =COUNTIF($F$2:$F7,AH$1) -> 0
A8: 7 | B8: 39915 | C8: 2007-2009 | D8: Yes | E8: AC Baby | F8: Siri | G8: =countif(H8:R8,"Yes") -> 6 | H8: Yes | I8: No | K8: Yes | L8: Yes | N8: Yes | P8: Yes | R8: Yes | V8: =COUNTIF($F$2:$F8,V$1) -> 0 | W8: =COUNTIF($F$2:$F8,W$1) -> 2 | X8: =COUNTIF($F$2:$F8,X$1) -> 0 | Y8: =COUNTIF($F$2:$F8,Y$1) -> 0 | Z8: =COUNTIF($F$2:$F8,Z$1) -> 1 | AA8: =COUNTIF($F$2:$F8,AA$1) -> 0 | AB8: =COUNTIF($F$2:$F8,AB$1) -> 0 | AC8: =COUNTIF($F$2:$F8,AC$1) -> 0 | ... AH8: =COUNTIF($F$2:$F8,AH$1) -> 0
A9: 8 | B9: 39940 | C9: 2007-2009 | D9: No | E9: Moe | F9: Princess Peach | G9: =countif(H9:R9,"Yes") -> 7 | H9: Yes | I9: Yes | K9: Yes | L9: Yes | N9: Yes | P9: Yes | R9: Yes | V9: =COUNTIF($F$2:$F9,V$1) -> 0 | W9: =COUNTIF($F$2:$F9,W$1) -> 2 | X9: =COUNTIF($F$2:$F9,X$1) -> 0 | Y9: =COUNTIF($F$2:$F9,Y$1) -> 0 | Z9: =COUNTIF($F$2:$F9,Z$1) -> 1 | AA9: =COUNTIF($F$2:$F9,AA$1) -> 0 | AB9: =COUNTIF($F$2:$F9,AB$1) -> 1 | AC9: =COUNTIF($F$2:$F9,AC$1) -> 0 | ... AH9: =COUNTIF($F$2:$F9,AH$1) -> 0
A10: 9 | B10: 40056 | C10: 2009-2010 | D10: No | E10: Waxcuses | F10: Waxcuses | G10: =countif(H10:R10,"Yes") -> 7 | H10: Yes | I10: Yes | K10: Yes | L10: Yes | N10: Yes | P10: Yes | R10: Yes | V10: =COUNTIF($F$2:$F10,V$1) -> 0 | W10: =COUNTIF($F$2:$F10,W$1) -> 2 | X10: =COUNTIF($F$2:$F10,X$1) -> 0 | Y10: =COUNTIF($F$2:$F10,Y$1) -> 0 | Z10: =COUNTIF($F$2:$F10,Z$1) -> 1 | AA10: =COUNTIF($F$2:$F10,AA$1) -> 0 | AB10: =COUNTIF($F$2:$F10,AB$1) -> 1 | AC10: =COUNTIF($F$2:$F10,AC$1) -> 0 | ... AH10: =COUNTIF($F$2:$F10,AH$1) -> 0
A11: 10 | B11: 40080 | C11: 2009-2010 | D11: No | E11: Siri | F11: Moe | G11: =countif(H11:R11,"Yes") -> 7 | H11: Yes | I11: Yes | K11: Yes | L11: Yes | N11: Yes | P11: Yes | R11: Yes | V11: =COUNTIF($F$2:$F11,V$1) -> 0 | W11: =COUNTIF($F$2:$F11,W$1) -> 2 | X11: =COUNTIF($F$2:$F11,X$1) -> 0 | Y11: =COUNTIF($F$2:$F11,Y$1) -> 0 | Z11: =COUNTIF($F$2:$F11,Z$1) -> 2 | AA11: =COUNTIF($F$2:$F11,AA$1) -> 0 | AB11: =COUNTIF($F$2:$F11,AB$1) -> 1 | AC11: =COUNTIF($F$2:$F11,AC$1) -> 0 | ... AH11: =COUNTIF($F$2:$F11,AH$1) -> 0
A12: 11 | B12: 40101 | C12: 2009-2010 | D12: No | E12: Andre | F12: Coach | G12: =countif(H12:R12,"Yes") -> 7 | H12: Yes | I12: Yes | K12: Yes | L12: Yes | N12: Yes | P12: Yes | R12: Yes | V12: =COUNTIF($F$2:$F12,V$1) -> 0 | W12: =COUNTIF($F$2:$F12,W$1) -> 3 | X12: =COUNTIF($F$2:$F12,X$1) -> 0 | Y12: =COUNTIF($F$2:$F12,Y$1) -> 0 | Z12: =COUNTIF($F$2:$F12,Z$1) -> 2 | AA12: =COUNTIF($F$2:$F12,AA$1) -> 0 | AB12: =COUNTIF($F$2:$F12,AB$1) -> 1 | AC12: =COUNTIF($F$2:$F12,AC$1) -> 0 | ... AH12: =COUNTIF($F$2:$F12,AH$1) -> 0
A13: 12 | B13: 40150 | C13: 2009-2010 | D13: No | E13: Princess Peach | F13: Princess Peach | G13: =countif(H13:R13,"Yes") -> 7 | H13: Yes | I13: Yes | K13: Yes | L13: Yes | N13: Yes | P13: Yes | R13: Yes | V13: =COUNTIF($F$2:$F13,V$1) -> 0 | W13: =COUNTIF($F$2:$F13,W$1) -> 3 | X13: =COUNTIF($F$2:$F13,X$1) -> 0 | Y13: =COUNTIF($F$2:$F13,Y$1) -> 0 | Z13: =COUNTIF($F$2:$F13,Z$1) -> 2 | AA13: =COUNTIF($F$2:$F13,AA$1) -> 0 | AB13: =COUNTIF($F$2:$F13,AB$1) -> 2 | AC13: =COUNTIF($F$2:$F13,AC$1) -> 0 | ... AH13: =COUNTIF($F$2:$F13,AH$1) -> 0
... A21: 20 | B21: 40444 | C21: 2010-2011 | D21: No | E21: Princess Peach | F21: Siri | G21: =countif(H21:R21,"Yes") -> 6 | H21: Yes | I21: Yes | K21: No | L21: Yes | N21: Yes | P21: Yes | R21: Yes | V21: =COUNTIF($F$2:$F21,V$1) -> 0 | W21: =COUNTIF($F$2:$F21,W$1) -> 4 | X21: =COUNTIF($F$2:$F21,X$1) -> 0 | Y21: =COUNTIF($F$2:$F21,Y$1) -> 2 | Z21: =COUNTIF($F$2:$F21,Z$1) -> 3 | AA21: =COUNTIF($F$2:$F21,AA$1) -> 0 | AB21: =COUNTIF($F$2:$F21,AB$1) -> 3 | AC21: =COUNTIF($F$2:$F21,AC$1) -> 0 | ... AH21: =COUNTIF($F$2:$F21,AH$1) -> 0
A22: 21 | B22: 40479 | C22: 2010-2011 | D22: No | E22: Siri | F22: Screech | G22: =countif(H22:R22,"Yes") -> 6 | H22: Yes | I22: Yes | K22: No | L22: Yes | N22: No | O22: Yes | P22: Yes | R22: Yes | V22: =COUNTIF($F$2:$F22,V$1) -> 0 | W22: =COUNTIF($F$2:$F22,W$1) -> 4 | X22: =COUNTIF($F$2:$F22,X$1) -> 0 | Y22: =COUNTIF($F$2:$F22,Y$1) -> 2 | Z22: =COUNTIF($F$2:$F22,Z$1) -> 3 | AA22: =COUNTIF($F$2:$F22,AA$1) -> 0 | AB22: =COUNTIF($F$2:$F22,AB$1) -> 3 | AC22: =COUNTIF($F$2:$F22,AC$1) -> 1 | ... AH22: =COUNTIF($F$2:$F22,AH$1) -> 0
A23: 22 | B23: 40515 | C23: 2010-2011 | D23: No | E23: Moe | F23: Princess Peach | G23: =countif(H23:R23,"Yes") -> 5 | H23: No | I23: Yes | K23: No | L23: Yes | N23: Yes | O23: Yes | P23: Yes | R23: No | V23: =COUNTIF($F$2:$F23,V$1) -> 0 | W23: =COUNTIF($F$2:$F23,W$1) -> 4 | X23: =COUNTIF($F$2:$F23,X$1) -> 0 | Y23: =COUNTIF($F$2:$F23,Y$1) -> 2 | Z23: =COUNTIF($F$2:$F23,Z$1) -> 3 | AA23: =COUNTIF($F$2:$F23,AA$1) -> 0 | AB23: =COUNTIF($F$2:$F23,AB$1) -> 4 | AC23: =COUNTIF($F$2:$F23,AC$1) -> 1 | ... AH23: =COUNTIF($F$2:$F23,AH$1) -> 0
A24: 23 | B24: 40541 | C24: 2010-2011 | D24: No | E24: Coach | F24: Siri | G24: =countif(H24:R24,"Yes") -> 7 | H24: Yes | I24: Yes | K24: No | L24: Yes | N24: Yes | O24: Yes | P24: Yes | R24: Yes | V24: =COUNTIF($F$2:$F24,V$1) -> 0 | W24: =COUNTIF($F$2:$F24,W$1) -> 4 | X24: =COUNTIF($F$2:$F24,X$1) -> 0 | Y24: =COUNTIF($F$2:$F24,Y$1) -> 2 | Z24: =COUNTIF($F$2:$F24,Z$1) -> 3 | AA24: =COUNTIF($F$2:$F24,AA$1) -> 0 | AB24: =COUNTIF($F$2:$F24,AB$1) -> 4 | AC24: =COUNTIF($F$2:$F24,AC$1) -> 1 | ... AH24: =COUNTIF($F$2:$F24,AH$1) -> 0
A25: 24 | B25: 40570 | C25: 2010-2011 | D25: No | E25: Waxcuses | F25: Coach | G25: =countif(H25:R25,"Yes") -> 6 | H25: Yes | I25: Yes | K25: No | L25: Yes | N25: Yes | O25: No | P25: Yes | R25: Yes | V25: =COUNTIF($F$2:$F25,V$1) -> 0 | W25: =COUNTIF($F$2:$F25,W$1) -> 5 | X25: =COUNTIF($F$2:$F25,X$1) -> 0 | Y25: =COUNTIF($F$2:$F25,Y$1) -> 2 | Z25: =COUNTIF($F$2:$F25,Z$1) -> 3 | AA25: =COUNTIF($F$2:$F25,AA$1) -> 0 | AB25: =COUNTIF($F$2:$F25,AB$1) -> 4 | AC25: =COUNTIF($F$2:$F25,AC$1) -> 1 | ... AH25: =COUNTIF($F$2:$F25,AH$1) -> 0
A26: 25 | B26: 40605 | C26: 2010-2011 | D26: No | E26: Siri | F26: Masta Pu$$y | G26: =countif(H26:R26,"Yes") -> 8 | H26: Yes | I26: Yes | K26: Yes | L26: Yes | N26: Yes | O26: Yes | P26: Yes | R26: Yes | V26: =COUNTIF($F$2:$F26,V$1) -> 0 | W26: =COUNTIF($F$2:$F26,W$1) -> 5 | X26: =COUNTIF($F$2:$F26,X$1) -> 0 | Y26: =COUNTIF($F$2:$F26,Y$1) -> 3 | Z26: =COUNTIF($F$2:$F26,Z$1) -> 3 | AA26: =COUNTIF($F$2:$F26,AA$1) -> 0 | AB26: =COUNTIF($F$2:$F26,AB$1) -> 4 | AC26: =COUNTIF($F$2:$F26,AC$1) -> 1 | ... AH26: =COUNTIF($F$2:$F26,AH$1) -> 0
A27: 26 | B27: 40621 | C27: 2010-2011 | D27: Yes | E27: ESSOP | F27: Siri | G27: =countif(H27:R27,"Yes") -> 6 | H27: Yes | I27: Yes | K27: Yes | L27: Yes | N27: No | O27: Yes | P27: Yes | R27: No | V27: =COUNTIF($F$2:$F27,V$1) -> 0 | W27: =COUNTIF($F$2:$F27,W$1) -> 5 | X27: =COUNTIF($F$2:$F27,X$1) -> 0 | Y27: =COUNTIF($F$2:$F27,Y$1) -> 3 | Z27: =COUNTIF($F$2:$F27,Z$1) -> 3 | AA27: =COUNTIF($F$2:$F27,AA$1) -> 0 | AB27: =COUNTIF($F$2:$F27,AB$1) -> 4 | AC27: =COUNTIF($F$2:$F27,AC$1) -> 1 | ... AH27: =COUNTIF($F$2:$F27,AH$1) -> 0
A28: 27 | B28: 40654 | C28: 2010-2011 | D28: Yes | E28: AC Baby | F28: Screech | G28: =countif(H28:R28,"Yes") -> 6 | H28: No | I28: No | K28: Yes | L28: Yes | N28: Yes | O28: Yes | P28: Yes | R28: Yes | V28: =COUNTIF($F$2:$F28,V$1) -> 0 | W28: =COUNTIF($F$2:$F28,W$1) -> 5 | X28: =COUNTIF($F$2:$F28,X$1) -> 0 | Y28: =COUNTIF($F$2:$F28,Y$1) -> 3 | Z28: =COUNTIF($F$2:$F28,Z$1) -> 3 | AA28: =COUNTIF($F$2:$F28,AA$1) -> 0 | AB28: =COUNTIF($F$2:$F28,AB$1) -> 4 | AC28: =COUNTIF($F$2:$F28,AC$1) -> 2 | ... AH28: =COUNTIF($F$2:$F28,AH$1) -> 0
A29: 28 | B29: 40671 | C29: 2010-2011 | D29: Yes | E29: Vegas Baby | F29: Masta Pu$$y | G29: =countif(H29:R29,"Yes") -> 4 | H29: No | I29: No | K29: Yes | L29: No | N29: Yes | O29: No | P29: Yes | R29: Yes | V29: =COUNTIF($F$2:$F29,V$1) -> 0 | W29: =COUNTIF($F$2:$F29,W$1) -> 5 | X29: =COUNTIF($F$2:$F29,X$1) -> 0 | Y29: =COUNTIF($F$2:$F29,Y$1) -> 4 | Z29: =COUNTIF($F$2:$F29,Z$1) -> 3 | AA29: =COUNTIF($F$2:$F29,AA$1) -> 0 | AB29: =COUNTIF($F$2:$F29,AB$1) -> 4 | AC29: =COUNTIF($F$2:$F29,AC$1) -> 2 | ... AH29: =COUNTIF($F$2:$F29,AH$1) -> 0
A30: 29 | B30: 40695 | C30: 2010-2011 | D30: No | E30: Princess Peach | F30: Coach | G30: =countif(H30:R30,"Yes") -> 5 | H30: No | I30: Yes | K30: No | L30: Yes | N30: Yes | O30: No | P30: Yes | R30: Yes | V30: =COUNTIF($F$2:$F30,V$1) -> 0 | W30: =COUNTIF($F$2:$F30,W$1) -> 6 | X30: =COUNTIF($F$2:$F30,X$1) -> 0 | Y30: =COUNTIF($F$2:$F30,Y$1) -> 4 | Z30: =COUNTIF($F$2:$F30,Z$1) -> 3 | AA30: =COUNTIF($F$2:$F30,AA$1) -> 0 | AB30: =COUNTIF($F$2:$F30,AB$1) -> 4 | AC30: =COUNTIF($F$2:$F30,AC$1) -> 2 | ... AH30: =COUNTIF($F$2:$F30,AH$1) -> 0
A31: 30 | B31: 40759 | C31: 2011-2012 | D31: No | E31: Andre | F31: Moe | G31: =countif(H31:R31,"Yes") -> 7 | H31: Yes | I31: Yes | K31: No | L31: Yes | N31: Yes | O31: Yes | P31: Yes | R31: Yes | V31: =COUNTIF($F$2:$F31,V$1) -> 0 | W31: =COUNTIF($F$2:$F31,W$1) -> 6 | X31: =COUNTIF($F$2:$F31,X$1) -> 0 | Y31: =COUNTIF($F$2:$F31,Y$1) -> 4 | Z31: =COUNTIF($F$2:$F31,Z$1) -> 4 | AA31: =COUNTIF($F$2:$F31,AA$1) -> 0 | AB31: =COUNTIF($F$2:$F31,AB$1) -> 4 | AC31: =COUNTIF($F$2:$F31,AC$1) -> 2 | ... AH31: =COUNTIF($F$2:$F31,AH$1) -> 0
A32: 31 | B32: 40800 | C32: 2011-2012 | D32: No | E32: Moe | F32: Waxcuses | G32: =countif(H32:R32,"Yes") -> 7 | H32: Yes | I32: Yes | K32: Yes | L32: Yes | N32: No | O32: Yes | P32: Yes | R32: Yes | V32: =COUNTIF($F$2:$F32,V$1) -> 0 | W32: =COUNTIF($F$2:$F32,W$1) -> 6 | X32: =COUNTIF($F$2:$F32,X$1) -> 0 | Y32: =COUNTIF($F$2:$F32,Y$1) -> 4 | Z32: =COUNTIF($F$2:$F32,Z$1) -> 4 | AA32: =COUNTIF($F$2:$F32,AA$1) -> 0 | AB32: =COUNTIF($F$2:$F32,AB$1) -> 4 | AC32: =COUNTIF($F$2:$F32,AC$1) -> 2 | ... AH32: =COUNTIF($F$2:$F32,AH$1) -> 0
A33: 32 | B33: 40815 | C33: 2011-2012 | D33: No | E33: Andre | F33: Screech | G33: =countif(H33:R33,"Yes") -> 6 | H33: Yes | I33: Yes | K33: Yes | L33: No | N33: Yes | O33: Yes | P33: Yes | R33: No | V33: =COUNTIF($F$2:$F33,V$1) -> 0 | W33: =COUNTIF($F$2:$F33,W$1) -> 6 | X33: =COUNTIF($F$2:$F33,X$1) -> 0 | Y33: =COUNTIF($F$2:$F33,Y$1) -> 4 | Z33: =COUNTIF($F$2:$F33,Z$1) -> 4 | AA33: =COUNTIF($F$2:$F33,AA$1) -> 0 | AB33: =COUNTIF($F$2:$F33,AB$1) -> 4 | AC33: =COUNTIF($F$2:$F33,AC$1) -> 3 | ... AH33: =COUNTIF($F$2:$F33,AH$1) -> 0
... A49: 48 | B49: 41327 | C49: 2012-2013 | D49: No | E49: Moe | F49: Masta Pu$$y | G49: =countif(H49:R49,"Yes") -> 7 | H49: Yes | I49: Yes | K49: Yes | L49: Yes | N49: No | O49: Yes | P49: Yes | R49: Yes | V49: =COUNTIF($F$2:$F49,V$1) -> 0 | W49: =COUNTIF($F$2:$F49,W$1) -> 7 | X49: =COUNTIF($F$2:$F49,X$1) -> 0 | Y49: =COUNTIF($F$2:$F49,Y$1) -> 5 | Z49: =COUNTIF($F$2:$F49,Z$1) -> 7 | AA49: =COUNTIF($F$2:$F49,AA$1) -> 0 | AB49: =COUNTIF($F$2:$F49,AB$1) -> 6 | AC49: =COUNTIF($F$2:$F49,AC$1) -> 6 | ... AH49: =COUNTIF($F$2:$F49,AH$1) -> 0
A50: 49 | B50: 41342 | C50: 2012-2013 | D50: Yes | E50: ESSOP | F50: Siri | G50: =countif(H50:R50,"Yes") -> 6 | H50: No | I50: Yes | K50: Yes | L50: Yes | M50: Yes | N50: No | O50: Yes | P50: Yes | R50: No | V50: =COUNTIF($F$2:$F50,V$1) -> 0 | W50: =COUNTIF($F$2:$F50,W$1) -> 7 | X50: =COUNTIF($F$2:$F50,X$1) -> 0 | Y50: =COUNTIF($F$2:$F50,Y$1) -> 5 | Z50: =COUNTIF($F$2:$F50,Z$1) -> 7 | AA50: =COUNTIF($F$2:$F50,AA$1) -> 0 | AB50: =COUNTIF($F$2:$F50,AB$1) -> 6 | AC50: =COUNTIF($F$2:$F50,AC$1) -> 6 | ... AH50: =COUNTIF($F$2:$F50,AH$1) -> 0
A51: 50 | B51: 41361 | C51: 2012-2013 | D51: Yes | E51: AC Baby | F51: Moe | G51: =countif(H51:R51,"Yes") -> 6 | H51: No | I51: Yes | K51: Yes | L51: Yes | M51: No | N51: No | O51: Yes | P51: Yes | R51: Yes | V51: =COUNTIF($F$2:$F51,V$1) -> 0 | W51: =COUNTIF($F$2:$F51,W$1) -> 7 | X51: =COUNTIF($F$2:$F51,X$1) -> 0 | Y51: =COUNTIF($F$2:$F51,Y$1) -> 5 | Z51: =COUNTIF($F$2:$F51,Z$1) -> 8 | AA51: =COUNTIF($F$2:$F51,AA$1) -> 0 | AB51: =COUNTIF($F$2:$F51,AB$1) -> 6 | AC51: =COUNTIF($F$2:$F51,AC$1) -> 6 | ... AH51: =COUNTIF($F$2:$F51,AH$1) -> 0
A52: 51 | B52: 41403 | C52: 2012-2013 | D52: No | E52: Screech | F52: Coach | G52: =countif(H52:R52,"Yes") -> 7 | H52: No | I52: Yes | K52: No | L52: Yes | M52: No | N52: Yes | O52: Yes | P52: Yes | Q52: Yes | R52: Yes | V52: =COUNTIF($F$2:$F52,V$1) -> 0 | W52: =COUNTIF($F$2:$F52,W$1) -> 8 | X52: =COUNTIF($F$2:$F52,X$1) -> 0 | Y52: =COUNTIF($F$2:$F52,Y$1) -> 5 | Z52: =COUNTIF($F$2:$F52,Z$1) -> 8 | AA52: =COUNTIF($F$2:$F52,AA$1) -> 0 | AB52: =COUNTIF($F$2:$F52,AB$1) -> 6 | AC52: =COUNTIF($F$2:$F52,AC$1) -> 6 | ... AH52: =COUNTIF($F$2:$F52,AH$1) -> 0
A53: 52 | B53: 41451 | C53: 2012-2013 | D53: No | E53: Coach | F53: Siri | G53: =countif(H53:R53,"Yes") -> 4 | H53: Yes | I53: Yes | K53: No | L53: Yes | M53: No | N53: No | O53: No | P53: Yes | Q53: No | R53: No | V53: =COUNTIF($F$2:$F53,V$1) -> 0 | W53: =COUNTIF($F$2:$F53,W$1) -> 8 | X53: =COUNTIF($F$2:$F53,X$1) -> 0 | Y53: =COUNTIF($F$2:$F53,Y$1) -> 5 | Z53: =COUNTIF($F$2:$F53,Z$1) -> 8 | AA53: =COUNTIF($F$2:$F53,AA$1) -> 0 | AB53: =COUNTIF($F$2:$F53,AB$1) -> 6 | AC53: =COUNTIF($F$2:$F53,AC$1) -> 6 | ... AH53: =COUNTIF($F$2:$F53,AH$1) -> 0
A54: 53 | B54: 41526 | C54: 2013-2014 | D54: No | E54: Waxcuses | F54: Moe | G54: =countif(H54:R54,"Yes") -> 7 | H54: Yes | I54: Yes | K54: Yes | L54: Yes | M54: No | N54: No | O54: Yes | P54: Yes | Q54: No | R54: Yes | V54: =COUNTIF($F$2:$F54,V$1) -> 0 | W54: =COUNTIF($F$2:$F54,W$1) -> 8 | X54: =COUNTIF($F$2:$F54,X$1) -> 0 | Y54: =COUNTIF($F$2:$F54,Y$1) -> 5 | Z54: =COUNTIF($F$2:$F54,Z$1) -> 9 | AA54: =COUNTIF($F$2:$F54,AA$1) -> 0 | AB54: =COUNTIF($F$2:$F54,AB$1) -> 6 | AC54: =COUNTIF($F$2:$F54,AC$1) -> 6 | ... AH54: =COUNTIF($F$2:$F54,AH$1) -> 0
A55: 54 | B55: 41558 | C55: 2013-2014 | D55: No | E55: Princess Peach | F55: Siri | G55: =countif(H55:R55,"Yes") -> 6 | H55: No | I55: No | K55: Yes | L55: Yes | M55: No | N55: Yes | O55: Yes | P55: Yes | Q55: No | R55: Yes | V55: =COUNTIF($F$2:$F55,V$1) -> 0 | W55: =COUNTIF($F$2:$F55,W$1) -> 8 | X55: =COUNTIF($F$2:$F55,X$1) -> 0 | Y55: =COUNTIF($F$2:$F55,Y$1) -> 5 | Z55: =COUNTIF($F$2:$F55,Z$1) -> 9 | AA55: =COUNTIF($F$2:$F55,AA$1) -> 0 | AB55: =COUNTIF($F$2:$F55,AB$1) -> 6 | AC55: =COUNTIF($F$2:$F55,AC$1) -> 6 | ... AH55: =COUNTIF($F$2:$F55,AH$1) -> 0
A56: 55 | B56: 41599 | C56: 2013-2014 | D56: No | E56: Siri | F56: The Bieb | G56: =countif(H56:R56,"Yes") -> 9 | H56: Yes | I56: Yes | K56: Yes | L56: Yes | M56: Yes | N56: No | O56: Yes | P56: Yes | Q56: Yes | R56: Yes | V56: =COUNTIF($F$2:$F56,V$1) -> 0 | W56: =COUNTIF($F$2:$F56,W$1) -> 8 | X56: =COUNTIF($F$2:$F56,X$1) -> 0 | Y56: =COUNTIF($F$2:$F56,Y$1) -> 5 | Z56: =COUNTIF($F$2:$F56,Z$1) -> 9 | AA56: =COUNTIF($F$2:$F56,AA$1) -> 0 | AB56: =COUNTIF($F$2:$F56,AB$1) -> 6 | AC56: =COUNTIF($F$2:$F56,AC$1) -> 6 | ... AH56: =COUNTIF($F$2:$F56,AH$1) -> 0
A57: 56 | B57: 41635 | C57: 2013-2014 | D57: Yes | E57: DP Open | F57: Coach | G57: =countif(H57:R57,"Yes") -> 5 | H57: No | I57: Yes | K57: Yes | L57: Yes | M57: No | N57: No | O57: Yes | P57: Yes | Q57: No | R57: No | V57: =COUNTIF($F$2:$F57,V$1) -> 0 | W57: =COUNTIF($F$2:$F57,W$1) -> 9 | X57: =COUNTIF($F$2:$F57,X$1) -> 0 | Y57: =COUNTIF($F$2:$F57,Y$1) -> 5 | Z57: =COUNTIF($F$2:$F57,Z$1) -> 9 | AA57: =COUNTIF($F$2:$F57,AA$1) -> 0 | AB57: =COUNTIF($F$2:$F57,AB$1) -> 6 | AC57: =COUNTIF($F$2:$F57,AC$1) -> 6 | ... AH57: =COUNTIF($F$2:$F57,AH$1) -> 0
A58: 57 | B58: 41648 | C58: 2013-2014 | D58: No | E58: Andre | F58: Screech | G58: =countif(H58:R58,"Yes") -> 7 | H58: Yes | I58: Yes | K58: Yes | L58: Yes | M58: No | N58: No | O58: Yes | P58: Yes | Q58: No | R58: Yes | V58: =COUNTIF($F$2:$F58,V$1) -> 0 | W58: =COUNTIF($F$2:$F58,W$1) -> 9 | X58: =COUNTIF($F$2:$F58,X$1) -> 0 | Y58: =COUNTIF($F$2:$F58,Y$1) -> 5 | Z58: =COUNTIF($F$2:$F58,Z$1) -> 9 | AA58: =COUNTIF($F$2:$F58,AA$1) -> 0 | AB58: =COUNTIF($F$2:$F58,AB$1) -> 6 | AC58: =COUNTIF($F$2:$F58,AC$1) -> 7 | ... AH58: =COUNTIF($F$2:$F58,AH$1) -> 0
A59: 58 | B59: 41674 | C59: 2013-2014 | D59: No | E59: Moe | F59: Princess Peach | G59: =countif(H59:R59,"Yes") -> 7 | H59: Yes | I59: Yes | K59: Yes | L59: Yes | M59: No | N59: Yes | O59: Yes | P59: Yes | Q59: No | R59: No | V59: =COUNTIF($F$2:$F59,V$1) -> 0 | W59: =COUNTIF($F$2:$F59,W$1) -> 9 | X59: =COUNTIF($F$2:$F59,X$1) -> 0 | Y59: =COUNTIF($F$2:$F59,Y$1) -> 5 | Z59: =COUNTIF($F$2:$F59,Z$1) -> 9 | AA59: =COUNTIF($F$2:$F59,AA$1) -> 0 | AB59: =COUNTIF($F$2:$F59,AB$1) -> 7 | AC59: =COUNTIF($F$2:$F59,AC$1) -> 7 | ... AH59: =COUNTIF($F$2:$F59,AH$1) -> 0
A60: 59 | B60: 41697 | C60: 2013-2014 | D60: No | E60: Screech | F60: Coach | G60: =countif(H60:R60,"Yes") -> 7 | H60: Yes | I60: Yes | J60: Yes | K60: Yes | L60: Yes | M60: Yes | N60: No | O60: No | P60: Yes | Q60: No | R60: No | V60: =COUNTIF($F$2:$F60,V$1) -> 0 | W60: =COUNTIF($F$2:$F60,W$1) -> 10 | X60: =COUNTIF($F$2:$F60,X$1) -> 0 | Y60: =COUNTIF($F$2:$F60,Y$1) -> 5 | Z60: =COUNTIF($F$2:$F60,Z$1) -> 9 | AA60: =COUNTIF($F$2:$F60,AA$1) -> 0 | AB60: =COUNTIF($F$2:$F60,AB$1) -> 7 | AC60: =COUNTIF($F$2:$F60,AC$1) -> 7 | ... AH60: =COUNTIF($F$2:$F60,AH$1) -> 0
A61: 60 | B61: 41720 | C61: 2013-2014 | D61: Yes | E61: ESSOP | F61: Mrs. Clay Matthews | G61: =countif(H61:R61,"Yes") -> 8 | H61: Yes | I61: Yes | J61: No | K61: Yes | L61: Yes | M61: Yes | N61: No | O61: Yes | P61: Yes | Q61: Yes | R61: No | V61: =COUNTIF($F$2:$F61,V$1) -> 0 | W61: =COUNTIF($F$2:$F61,W$1) -> 10 | X61: =COUNTIF($F$2:$F61,X$1) -> 0 | Y61: =COUNTIF($F$2:$F61,Y$1) -> 5 | Z61: =COUNTIF($F$2:$F61,Z$1) -> 9 | AA61: =COUNTIF($F$2:$F61,AA$1) -> 1 | AB61: =COUNTIF($F$2:$F61,AB$1) -> 7 | AC61: =COUNTIF($F$2:$F61,AC$1) -> 7 | ... AH61: =COUNTIF($F$2:$F61,AH$1) -> 0
A62: 61 | B62: 41746 | C62: 2013-2014 | D62: Yes | E62: AC Baby | F62: Siri | G62: =countif(H62:R62,"Yes") -> 7 | H62: Yes | I62: Yes | J62: No | K62: Yes | L62: Yes | M62: No | N62: No | O62: Yes | P62: Yes | Q62: No | R62: Yes | V62: =COUNTIF($F$2:$F62,V$1) -> 0 | W62: =COUNTIF($F$2:$F62,W$1) -> 10 | X62: =COUNTIF($F$2:$F62,X$1) -> 0 | Y62: =COUNTIF($F$2:$F62,Y$1) -> 5 | Z62: =COUNTIF($F$2:$F62,Z$1) -> 9 | AA62: =COUNTIF($F$2:$F62,AA$1) -> 1 | AB62: =COUNTIF($F$2:$F62,AB$1) -> 7 | AC62: =COUNTIF($F$2:$F62,AC$1) -> 7 | ... AH62: =COUNTIF($F$2:$F62,AH$1) -> 0
...

Sheet Bracelets v. Time

Sheet Bracelets Pivot

Sheet Majors Pivot

Sheet Win Rate
A1: Player | B1: Andre | C1: Coach | D1: Junior | E1: Masta Pu$$y | F1: Moe | G1: Mrs. Clay Matthews | H1: Princess Peach | I1: Screech | J1: Siri | K1: The Bieb | L1: Waxcuses
A2: Nights Attended | B2: =countif('Raw Data'!H:H,"YES") -> 162 | C2: =countif('Raw Data'!I:I,"YES") -> 178 | D2: =countif('Raw Data'!J:J,"YES") -> 106 | E2: =countif('Raw Data'!K:K,"YES") -> 134 | F2: =countif('Raw Data'!L:L,"YES") -> 189 | G2: =countif('Raw Data'!M:M,"YES") -> 108 | H2: =countif('Raw Data'!N:N,"YES") -> 36 | I2: =countif('Raw Data'!O:O,"YES") -> 119 | J2: =countif('Raw Data'!P:P,"YES") -> 178 | K2: =countif('Raw Data'!Q:Q,"YES") -> 63 | L2: =countif('Raw Data'!R:R,"YES") -> 120
A3: Bracelets Won | B3: =vlookup(B1,'Bracelets Pivot'!$A2:$B13,2,FALSE) -> 9 | C3: =vlookup(C1,'Bracelets Pivot'!$A2:$B13,2,FALSE) -> 30 | D3: =vlookup(D1,'Bracelets Pivot'!$A2:$B13,2,FALSE) -> 12 | E3: =vlookup(E1,'Bracelets Pivot'!$A2:$B13,2,FALSE) -> 17 | F3: =vlookup(F1,'Bracelets Pivot'!$A2:$B13,2,FALSE) -> 30 | G3: =vlookup(G1,'Bracelets Pivot'!$A2:$B13,2,FALSE) -> 8 | H3: =vlookup(H1,'Bracelets Pivot'!$A2:$B13,2,FALSE) -> 7 | I3: =vlookup(I1,'Bracelets Pivot'!$A2:$B13,2,FALSE) -> 28 | ... L3: =vlookup(L1,'Bracelets Pivot'!$A2:$B13,2,FALSE) -> 14
A4: Bracelet Win Rate | B4: =B3/B2 -> 0.055555556 | C4: =C3/C2 -> 0.16853933 | D4: =D3/D2 -> 0.11320755 | E4: =E3/E2 -> 0.12686567 | F4: =F3/F2 -> 0.15873016 | G4: =G3/G2 -> 0.074074074 | H4: =H3/H2 -> 0.19444444 | I4: =I3/I2 -> 0.23529412 | ... L4: =L3/L2 -> 0.11666667
A6: Screech | B6: =$I$4 -> 0.23529412
A7: Princess Peach | B7: =$H$4 -> 0.19444444
A8: Siri | B8: =$J$4 -> 0.19662921
A9: Moe | B9: =$F$4 -> 0.15873016
A10: Coach | B10: =$C$4 -> 0.16853933
A11: Masta Pu$$y | B11: =$E$4 -> 0.12686567
A12: Waxcuses | B12: =$L$4 -> 0.11666667
A13: Junior | B13: =$D$4 -> 0.11320755
A14: The Bieb | B14: =$K$4 -> 0.11111111
A15: Mrs. Clay Matthews | B15: =$G$4 -> 0.074074074
A16: Andre | B16: =$B$4 -> 0.055555556
A18: Coach | B18: =$C$4 -> 0.16853933

Sheet Host Order
A1: Names | C1: 2025 Host Order | D1: Last Hosted
A2: Andre | C2: Siri | D2: 45682
A3: Coach | C3: Coach | D3: 45713
A4: Flo Rida | C4: Screech | D4: 45741
A5: Junior | C5: AC BABY | D5: 45772
A6: Masta Pu$$y | C6: Andre | D6: 45802
A7: Moe | C7: Waxcuses | D7: 45833
A8: Mrs. Clay Matthews | C8: The Bieb | D8: 45863
A9: No Limit | C9: Moe | D9: 45894
A10: Princess Peach | C10: Junior | D10: 45925
A11: Screech | C11: Mrs. Clay Matthews | D11: 45955
A12: Siri | C12: No Limit | D12: 45986
A13: The Bieb | C13: Hold'em Holidays | D13: 46016 | E13: Flo Rida and Screech
A14: Waxcuses | C14: Siri | D14: 46047
A15: AC Baby | C15: Coach | D15: 46078 | E15: 15-25-55-200 celebration
A16: None (Virtual) | C16: Andre | D16: 46106
C17: AC BABY | D17: 46137
C18: Waxcuses | D18: 46167
C19: Moe | D19: 46198 | E19: Double Hundge
C20: The Bieb | D20: 46228 | E20: Battle of the Clams
C21: Junior | D21: 46259
C22: North Carolina??? | D22: 46290
C23: Mrs. Clay Matthews | D23: 46320
C24: No Limit | D24: 46351
C25: Hold'em Holidays | D25: 46381 | E25: Flo Rida and Screech

Sheet Matrix
C2: 46155 | D2: 46161 | E2: 46162 | G2: P | H2: 1
B3: Andre | C3: 1 | D3: 1 | E3: 1 | G3: Q | H3: 0.5
B4: Bieb | C4: 0.25 | D4: 0.25 | E4: 0.5 | G4: D | H4: 0.25
B5: Coach | C5: 1 | D5: 0.25 | E5: 0.5 | G5: O | H5: 0
B6: Flo Rida | C6: 1 | D6: 0 | E6: 0
B7: Junior | C7: 1 | D7: 1 | E7: 1
B8: Masta Pu$$y | C8: 0 | D8: 0.5 | E8: 0
B9: Moe | C9: 1 | D9: 1 | E9: 1
B10: Mrs. Clay | C10: 1 | D10: 1 | E10: 1
B11: No Limit | C11: 0.5 | D11: 0.5 | E11: 0.5
B12: Screech | C12: 1 | D12: 0 | E12: 1
B13: Siri | C13: 1 | D13: 0.5 | E13: 1
B14: Waxcuses | C14: 1 | D14: 1 | E14: 1
B16: Matrix Result | C16: =sum(C3:C14) -> 9.75 | D16: =sum(D3:D14) -> 7 | E16: =sum(E3:E14) -> 8.5
B18: # of Probables | C18: =countif(C3:C14,1) -> 9 | D18: =countif(D3:D14,1) -> 5 | E18: =countif(E3:E14,1) -> 7
C21: 46083 | E21: 46084
B22: Andre | C22: 1 | E22: 1
B23: Bieb | C23: 0 | E23: 0
B24: Coach | C24: 1 | E24: 1
B25: Flo Rida | C25: 0 | E25: 0
B26: Junior | C26: 0 | E26: 0
B27: Masta Pu$$y | C27: 0 | E27: 0.5
B28: Moe | C28: 1 | E28: 1
B29: Mrs. Clay | C29: 0.5 | E29: 0.5
B30: No Limit | C30: 0.5 | E30: 1
B31: Screech | C31: 1 | E31: 0.5
B32: Siri | C32: 0.5 | E32: 0.5
B33: Waxcuses | C33: 1 | E33: 0.5
B35: Matrix Result | C35: =sum(C22:C33) -> 6.5 | E35: =sum(E22:E33) -> 6.5
B37: # of Probables | C37: =countif(C22:C33,1) -> 5 | E37: =countif(E22:E33,1) -> 4

Sheet Notes from Jeff (for early even

Sheet GOPT MM Contest
B1: 2005 APS NCAA DRAFT POOL
B2: 2025 GOPT March Madness Contest - Picksheet
O3: 1 | P3: 2 | Q3: 3 | R3: 4 | S3: 5 | T3: 6 | U3: 7 | V3: 8 | W3: 9 | X3: 10 | Y3: 11 | Z3: 12
C4: SOUTH | E4: EAST | G4: MIDWEST | I4: WEST | O4: ↓↓ | P4: ↑↑ | Q4: ↓↓ | R4: ↑↑ | S4: ↓↓ | T4: ↑↑ | U4: ↓↓ | V4: ↑↑ | W4: ↓↓ | X4: ↑↑ | Y4: ↓↓ | Z4: ↑↑
B5: 1 | C5: Auburn | E5: Duke | G5: Houston | I5: Florida | M5: 1 | N5: Andre | O5: Duke | P5: St. John's | Q5: Maryland | R5: Michigan | S5: Arizona | T5: Marquette | U5: Kansas | V5: St. Marys | W5: UCLA | X5: Arkansas | Y5: Yale | Z5: St. Francis
B6: 1 | C6: Auburn | E6: Duke | G6: Houston | I6: Florida | M6: 2 | N6: Mrs. Clay | O6: Auburn | P6: Michigan St. | Q6: Wisconsin | R6: Arizona | S6: Purdue | T6: Marquette | U6: Kansas | V6: UCLA | W6: St. Marys | X6: Vanderbilt | Y6: Grand Canyon | Z6: SDSU
B7: 1 | C7: Auburn | E7: Duke | G7: Houston | I7: Florida | M7: 3 | N7: Bieb | O7: Duke | P7: St. John's | Q7: Alabama | R7: Kentucky | S7: Texas A&M | T7: Illinois | U7: Marquette | V7: Baylor | W7: Louisville | X7: Oklahoma | Y7: Xavier | Z7: American
B8: 2 | C8: Michigan St. | E8: Alabama | G8: Tennessee | I8: St. John's | M8: 4 | N8: Siri | O8: Duke | P8: Tennessee | Q8: Alabama | R8: Kentucky | S8: Texas A&M | T8: Missouri | U8: Clemson | V8: Illinois | W8: BYU | X8: UCSD | Y8: Liberty | Z8: SIUE
B9: 2 | C9: Michigan St. | E9: Alabama | G9: Tennessee | I9: St. John's | M9: 5 | N9: Moe | O9: Auburn | P9: Tennessee | Q9: Texas Tech | R9: Arizona | S9: Texas A&M | T9: Illinois | U9: Connecticut | V9: Gonzaga | W9: St. Marys | X9: Texas | Y9: Alabama St | Z9: Wofford
B10: 2 | C10: Michigan St. | E10: Alabama | G10: Tennessee | I10: St. John's | M10: 6 | N10: Flo Rida | O10: Florida | P10: Tennessee | Q10: Wisconsin | R10: Iowa St. | S10: Michigan | T10: Drake | U10: VCU | V10: Georgia | W10: McNeese | X10: Colorado St. | Y10: Mt. St Mary's | Z10: Omaha
B11: 3 | C11: Iowa St. | E11: Wisconsin | G11: Kentucky | I11: Texas Tech | M11: 7 | N11: Junior | O11: Florida | P11: Michigan St. | Q11: Maryland | R11: Wisconsin | S11: Purdue | T11: Missouri | U11: Connecticut | V11: Gonzaga | W11: Ole Miss | X11: New Mexico | Y11: Norfolk St | Z11: Bryant
B12: 3 | C12: Iowa St. | E12: Wisconsin | G12: Kentucky | I12: Texas Tech | M12: 8 | N12: Wax | O12: Florida | P12: St. John's | Q12: Texas Tech | R12: Maryland | S12: Memphis | T12: Oregon | U12: Gonzaga | V12: Creighton | W12: Louisville | X12: Ole Miss | Y12: High Point | Z12: Montana
B13: 3 | C13: Iowa St. | E13: Wisconsin | G13: Kentucky | I13: Texas Tech | M13: 9 | N13: Screech | O13: Auburn | P13: Houston | Q13: Texas Tech | R13: Iowa St. | S13: Purdue | T13: Oregon | U13: UNC | V13: BYU | W13: Ole Miss | X13: Mississippi St | Y13: Utah St | Z13: Troy
B14: 4 | C14: Texas A&M | E14: Arizona | G14: Purdue | I14: Maryland | M14: 10 | N14: Masta P. | O14: Houston | P14: Michigan St. | Q14: Michigan | R14: Memphis | S14: Clemson | T14: Oregon | U14: BYU | V14: Connecticut | W14: Louisville | X14: Mississippi St | Y14: UNCW | Z14: Robert Morris
B15: 4 | C15: Texas A&M | E15: Arizona | G15: Purdue | I15: Maryland | M15: 11 | N15: Coach | O15: Alabama | P15: Houston | Q15: Iowa St. | R15: Kentucky | S15: Missouri | T15: Memphis | U15: Kansas | V15: Clemson | W15: Mississippi St | X15: UCLA | Y15: Lipscomb | Z15: Akron
B16: 4 | C16: Texas A&M | E16: Arizona | G16: Purdue | I16: Maryland
B17: 5 | C17: Michigan | E17: Oregon | G17: Clemson | I17: Memphis
B18: 5 | C18: Michigan | E18: Oregon | G18: Clemson | I18: Memphis
B19: 5 | C19: Michigan | E19: Oregon | G19: Clemson | I19: Memphis
B20: 6 | C20: Ole Miss | E20: BYU | G20: Illinois | I20: Missouri
B21: 6 | C21: Ole Miss | E21: BYU | G21: Illinois | I21: Missouri
B22: 6 | C22: Ole Miss | E22: BYU | G22: Illinois | I22: Missouri
B23: 7 | C23: Marquette | E23: St. Mary's | G23: UCLA | I23: Kansas
B24: 7 | C24: Marquette | E24: St. Mary's | G24: UCLA | I24: Kansas
B25: 7 | C25: Marquette | E25: St. Mary's | G25: UCLA | I25: Kansas
B26: 8 | C26: Louisville | E26: Mississippi St. | G26: Gonzaga | I26: Connecticut
B27: 8 | C27: Louisville | E27: Mississippi St. | G27: Gonzaga | I27: Connecticut
... B30: 10 | C30: New Mexico | E30: Vanderbilt | G30: Utah State | I30: Arkansas
B31: 11 | C31: SDSU | D31: UNC | E31: VCU | G31: Xavier | H31: Texas | I31: Drake
B32: 12 | C32: UC San Diego | E32: Liberty | G32: McNeese | I32: Colorado St.
B33: 13 | C33: Yale | E33: Akron | G33: High Point | I33: Grand Canyon
B34: 14 | C34: Lipscomb | E34: Montana | G34: Troy | I34: UNC Wilmington
B35: 15 | C35: Bryant | E35: Robert Morris | G35: Wofford | I35: Omaha
B36: 16 | C36: St. Francis | D36: Alabama St. | E36: Mt. St. Mary's | F36: American | G36: SIU Edwardsville | I36: Norfolk St.
